Workbook

Sheet Cover
A1: AI PLANT OPERATIONS OPTIMISER: INTEGRATED FINANCIAL MODEL, FY2027-FY2031
A2: Prepared 10-Oct-2026 for the IIM Kozhikode team; revised 10-Oct-2026 for financial viability (see 15_Change_Log). Proposed product; nothing here is commercially validated.
A4: How to use | B4: Change blue cells on 'Inputs' (and scenario prices on '3_Pricing'). Switch scenario with Inputs!C3 (1 Bear, 2 Base, 3 Bull). Everything else is formula-driven.
A6: Units | B6: ₹ lakh unless stated (₹1 crore = ₹100 lakh). Customer counts are expected values, so they can be fractional.
A8: Colour code | B8: Blue text, cream fill = input. Black = formula. Green = link from another sheet. Green fill = key output. Yellow = scenario switch / master check.
A10: Data status tags | B10: Inputs column G: 'Verified fact' (official or published source), 'Assumption' (management judgement), 'Validate' (must be tested with customers before the pitch).
A12: Engine | B12: 'Engine_Monthly' runs all 60 months (Apr-2026 to Mar-2031): funnel → pilots → contracts → implementation capacity → go-live → ARR → costs → P&L → cash → balance sheet. Annual sheets aggregate it.
A14: Timing note | B14: FY27 starts Apr-2026 as requested; six months have already elapsed. Move Inputs 'Model start date' to re-base.
A16: Snapshots | B16: '12_Scenarios' bear/base/bull and sensitivity tables, the NPV bridge on '15_Change_Log' and the FY27-FY31 scenario rows in 14_Valuation section F are values from full re-runs of this model. If you change engine inputs, re-run each case and read the LIVE column.
A18: Sheet map | B18: 1 Dashboard · Inputs · 2 Market · 3 Pricing · 4 Revenue build · 5 Cost of service · 6 Personnel & opex · 7 Financial statements · 8 Unit economics · 9 Customer ROI · 10 GTM · 11 Funding · 12 Scenarios · 13 Risks & checks · 14 Valuation · 15 Change log · Engine · Sources
A20: Revision | B20: Valuation: 14_Valuation (base DCF at the team's 12% WACC with a steady-state terminal value, probability-weighted scenarios, comparable-company cross-check, equity bridge). What changed versus the model as received, and the NPV bridge: 15_Change_Log.
A22: v4 update | B22: v4 (11-Oct-2026): TAM = 63,728 operating factories in 7 industries (ASI 2023-24); SAM via size, state and readiness filters; Year-5 live plants solved to 200 / 400 / 600; tiered pricing ₹12-60 lakh; gain-share on its own line. Bear / base / bull comparison and flags: 16_SOM_Scenarios. Changes: 15_Change_Log section F.

Sheet 1_Dashboard
A1: 1. EXECUTIVE DASHBOARD: AI PLANT OPERATIONS OPTIMISER (₹ lakh unless stated)
A3: Active scenario | C3: =Inputs!D3 -> BASE | E3: Model checks | F3: =IF(13_Risks_Checks!$B$22,"ALL PASS","CHECK 13_Risks_Checks") -> ALL PASS
A5: HEADLINES
A6: FY31 revenue | B6: ₹ crore | C6: =7_Financials!$G$11/100 -> 150.92972
A7: FY31 closing ARR | B7: ₹ crore | C7: =4_Revenue_Build!G30/100 -> 157.45778
A8: ="Live paying plants, end FY31 (target "&TEXT(Inputs!C151,"0")&")" -> Live paying plants, end FY31 (target 400) | B8: # | C8: =4_Revenue_Build!G21 -> 400.00001
A9: EBITDA break-even (first month trailing-3-month EBITDA > 0) | B9: month | C9: =IF(COUNT(Engine_Monthly!$D$176:$BK$176)=0,"Not within 5 years",TEXT(INDEX(Engine_Monthly!$D$9:$BK$9,1,MIN(Engine_Monthly!$D$176:$BK$176)),"mmm-yy")&" ("&INDEX(Engine_Monthly!$D$10:$BK$10,1,MIN(Engine_Monthly!$D$176:$BK$176))&")") -> Aug-28 (FY29)
A10: Peak cumulative cash deficit | B10: ₹ crore | C10: =11_Funding!C5/100 -> 6.9294953
A11: Total equity requirement incl. buffer & contingency | B11: ₹ crore | C11: =11_Funding!C11/100 -> 11.029115
A12: Seed requirement (to Series A) | B12: ₹ crore | C12: =11_Funding!C15/100 -> 9.7157586
A13: Live plants needed to cover FY31 cost base | B13: # | C13: =8_Unit_Economics!G33 -> 62.889947
A14: Customer value: gross benefit ÷ Professional price (Low / Base / High) | B14: x | C14: =TEXT(9_Customer_ROI!C52,"0.0")&"x / "&TEXT(9_Customer_ROI!D52,"0.0")&"x / "&TEXT(9_Customer_ROI!E52,"0.0")&"x" -> 0.7x / 3.9x / 12.6x
A15: Enterprise value @ 12%: base DCF (₹ crore; see 14_Valuation) | B15: ₹ crore | C15: =14_Valuation!C75 -> 367.69834
A16: Probability-weighted EV / comps range (EV/ARR) / base DCF at 20% (₹ crore) | B16: ₹ crore | C16: =TEXT(14_Valuation!F195,"0.0")&" / "&TEXT(14_Valuation!C225,"0.0")&"-"&TEXT(14_Valuation!E225,"0.0")&" / "&TEXT(14_Valuation!C86,"0.0") -> 503.1 / 315.5-672.9 / 161.4
A17: ANNUAL KPIs
A18: KPI | B18: Unit | C18: =INDEX(Engine_Monthly!$D$10:$BK$10,1,12) -> FY27 | D18: =INDEX(Engine_Monthly!$D$10:$BK$10,1,24) -> FY28 | E18: =INDEX(Engine_Monthly!$D$10:$BK$10,1,36) -> FY29 | F18: =INDEX(Engine_Monthly!$D$10:$BK$10,1,48) -> FY30 | G18: =INDEX(Engine_Monthly!$D$10:$BK$10,1,60) -> FY31
A19: Revenue | B19: ₹ lakh | C19: =7_Financials!C11 -> 28.637625 | D19: =7_Financials!D11 -> 478.84504 | E19: =7_Financials!E11 -> 2411.1478 | F19: =7_Financials!F11 -> 7026.3162 | G19: =7_Financials!G11 -> 15092.972
A20: Revenue growth | B20: % | C20: =7_Financials!C12 -> 0 | D20: =7_Financials!D12 -> 15.720836 | E20: =7_Financials!E12 -> 4.0353405 | F20: =7_Financials!F12 -> 1.914096 | G20: =7_Financials!G12 -> 1.1480633
A21: Closing ARR | B21: ₹ lakh | C21: =4_Revenue_Build!C30 -> 30.996799 | D21: =4_Revenue_Build!D30 -> 552.94498 | E21: =4_Revenue_Build!E30 -> 2619.6435 | F21: =4_Revenue_Build!F30 -> 7429.6244 | G21: =4_Revenue_Build!G30 -> 15745.778
A22: Closing MRR | B22: ₹ lakh | C22: =4_Revenue_Build!C32 -> 2.5830666 | D22: =4_Revenue_Build!D32 -> 46.078748 | E22: =4_Revenue_Build!E32 -> 218.30362 | F22: =4_Revenue_Build!F32 -> 619.13536 | G22: =4_Revenue_Build!G32 -> 1312.1482
A23: New paying customers (contracts) | B23: # | C23: =4_Revenue_Build!C13 -> 1.98 | D23: =4_Revenue_Build!D13 -> 23.57939 | E23: =4_Revenue_Build!E13 -> 75.260059 | F23: =4_Revenue_Build!F13 -> 152.50012 | G23: =4_Revenue_Build!G13 -> 237.16518
A24: Live paying plants (year end) | B24: # | C24: =4_Revenue_Build!C21 -> 1.0609353 | D24: =4_Revenue_Build!D21 -> 17.598591 | E24: =4_Revenue_Build!E21 -> 77.249595 | F24: =4_Revenue_Build!F21 -> 203.40003 | G24: =4_Revenue_Build!G21 -> 400.00001
A25: Active pilots at year end (not customers) | B25: # | C25: =4_Revenue_Build!C12 -> 3.6 | D25: =4_Revenue_Build!D12 -> 20.985809 | E25: =4_Revenue_Build!E12 -> 54.182426 | F25: =4_Revenue_Build!F12 -> 93.454044 | G25: =4_Revenue_Build!G12 -> 130.02566
A26: Gross margin | B26: % | C26: =7_Financials!C15 -> -0.57596702 | D26: =7_Financials!D15 -> 0.45347733 | E26: =7_Financials!E15 -> 0.65539399 | F26: =7_Financials!F15 -> 0.74060472 | G26: =7_Financials!G15 -> 0.79356308
A27: SaaS gross margin | B27: % | C27: =5_Cost_of_Service!C17 -> -3.9482785 | D27: =5_Cost_of_Service!D17 -> 0.59280881 | E27: =5_Cost_of_Service!E17 -> 0.84371307 | F27: =5_Cost_of_Service!F17 -> 0.89154548 | G27: =5_Cost_of_Service!G17 -> 0.91268428
A28: EBITDA | B28: ₹ lakh | C28: =7_Financials!C19 -> -203.33499 | D28: =7_Financials!D19 -> -349.49934 | E28: =7_Financials!E19 -> 354.79406 | F28: =7_Financials!F19 -> 3061.3425 | G28: =7_Financials!G19 -> 8786.0955
A29: EBITDA margin | B29: % | C29: =7_Financials!C20 -> -7.1002744 | D29: =7_Financials!D20 -> -0.72987986 | E29: =7_Financials!E20 -> 0.14714737 | F29: =7_Financials!F20 -> 0.43569666 | G29: =7_Financials!G20 -> 0.58213157
A30: Cash burn (operating + investing outflow) | B30: ₹ lakh | C30: =SUMIF(Engine_Monthly!$D$7:$BK$7,1,Engine_Monthly!$D$167:$BK$167) -> 223.80611 | D30: =SUMIF(Engine_Monthly!$D$7:$BK$7,2,Engine_Monthly!$D$167:$BK$167) -> 394.90198 | E30: =SUMIF(Engine_Monthly!$D$7:$BK$7,3,Engine_Monthly!$D$167:$BK$167) -> 74.241433 | F30: =SUMIF(Engine_Monthly!$D$7:$BK$7,4,Engine_Monthly!$D$167:$BK$167) -> 0 | G30: =SUMIF(Engine_Monthly!$D$7:$BK$7,5,Engine_Monthly!$D$167:$BK$167) -> 0
A31: Closing cash | B31: ₹ lakh | C31: =7_Financials!C43 -> 676.19389 | D31: =7_Financials!D43 -> 1181.2919 | E31: =7_Financials!E43 -> 1443.5127 | F31: =7_Financials!F43 -> 3674.9102 | G31: =7_Financials!G43 -> 10114.97
A32: CAC, fully loaded (estimate) | B32: ₹ lakh | C32: =8_Unit_Economics!C17 -> n.m. | D32: =8_Unit_Economics!D17 -> 12.999213 | E32: =8_Unit_Economics!E17 -> 10.792681 | F32: =8_Unit_Economics!F17 -> 10.221104 | G32: =8_Unit_Economics!G17 -> 10.058048
A33: LTV (estimate) | B33: ₹ lakh | C33: =8_Unit_Economics!C27 -> n.m. | D33: =8_Unit_Economics!D27 -> 46.240472 | E33: =8_Unit_Economics!E27 -> 76.878186 | F33: =8_Unit_Economics!F27 -> 89.481784 | G33: =8_Unit_Economics!G27 -> 99.817619
A34: LTV / CAC (estimate) | B34: x | C34: =8_Unit_Economics!C28 -> n.m. | D34: =8_Unit_Economics!D28 -> 3.5571747 | E34: =8_Unit_Economics!E28 -> 7.1231781 | F34: =8_Unit_Economics!F28 -> 8.7546108 | G34: =8_Unit_Economics!G28 -> 9.924154
A35: CAC payback (estimate) | B35: months | C35: =8_Unit_Economics!C29 -> n.m. | D35: =8_Unit_Economics!D29 -> 9.4132897 | E35: =8_Unit_Economics!E29 -> 4.8967909 | F35: =8_Unit_Economics!F29 -> 4.0194093 | G35: =8_Unit_Economics!G29 -> 3.5580541
A36: Annual logo churn (assumption) | B36: % | C36: =8_Unit_Economics!C21 -> 0.09 | D36: =8_Unit_Economics!D21 -> 0.09 | E36: =8_Unit_Economics!E21 -> 0.09 | F36: =8_Unit_Economics!F21 -> 0.09 | G36: =8_Unit_Economics!G21 -> 0.09
A37: Average ARR per live plant | B37: ₹ lakh | C37: =8_Unit_Economics!C7 -> 22.969133 | D37: =8_Unit_Economics!D7 -> 27.953889 | E37: =8_Unit_Economics!E7 -> 31.347596 | F37: =8_Unit_Economics!F7 -> 34.227352 | G37: =8_Unit_Economics!G7 -> 37.167371
A38: Headcount (year end) | B38: # | C38: =6_Personnel_Opex!C24 -> 11 | D38: =6_Personnel_Opex!D24 -> 25 | E38: =6_Personnel_Opex!E24 -> 53 | F38: =6_Personnel_Opex!F24 -> 88 | G38: =6_Personnel_Opex!G24 -> 128
A40: SCENARIO COMPARISON (snapshot; live column follows Inputs!C3)
A41: Output | B41: Unit | C41: Bear | D41: Base | E41: Bull | F41: Live
A42: =12_Scenarios!A28 -> FY31 revenue | B42: =12_Scenarios!B28 -> ₹ lakh | C42: =12_Scenarios!C28 -> 4938.4899 | D42: =12_Scenarios!D28 -> 15092.972 | E42: =12_Scenarios!E28 -> 31192.844 | F42: =12_Scenarios!F28 -> 15092.972
A43: =12_Scenarios!A29 -> FY31 closing ARR | B43: =12_Scenarios!B29 -> ₹ lakh | C43: =12_Scenarios!C29 -> 4678.5326 | D43: =12_Scenarios!D29 -> 15745.778 | E43: =12_Scenarios!E29 -> 33677.888 | F43: =12_Scenarios!F29 -> 15745.778
...

Sheet Inputs
A1: INPUTS & ASSUMPTIONS REGISTER (all values in ₹ lakh unless stated)
A2: Blue = hardcoded input. Black = formula. Green = link. Column C is what the model uses. Scenario-varied inputs have Bear / Base / Bull values; fixed inputs only a Base value. v4 (11-Oct-2026) inputs are in section K.
A3: ACTIVE SCENARIO (1 = Bear, 2 = Base, 3 = Bull) | C3: 2 | D3: =CHOOSE($C$3,"BEAR","BASE","BULL") -> BASE
A5: Parameter | B5: Unit | C5: ACTIVE | D5: Bear | E5: Base | F5: Bull | G5: Type | H5: Source / rationale | I5: Validation needed
A7: A. GENERAL & MACRO
A8: Model start date (first month of FY27) | B8: date | C8: =IF(D8="",E8,CHOOSE($C$3,D8,E8,F8)) -> 46113 | E8: 46113 | G8: Assumption | H8: FY2027 = Apr-2026 to Mar-2027 as requested. Months 1-6 have already elapsed at 10-Oct-2026; shift this date to re-base the whole model.
A9: USD / INR | B9: ₹ per $ | C9: =IF(D9="",E9,CHOOSE($C$3,D9,E9,F9)) -> 95 | E9: 95 | G9: Verified fact | H9: ~₹95-96 per USD in Aug-Sep 2026 (OFX 5-Aug-2026: 95.03; longforecast 16-Sep-2026: 95.95). Used only to convert $ benchmarks.
A10: Corporate tax rate (concessional 22% regime + 10% surcharge + 4% cess) | B10: % | C10: =IF(D10="",E10,CHOOSE($C$3,D10,E10,F10)) -> 0.25168 | E10: 0.25168 | G10: Verified fact | H10: Sec 200, Income-tax Act 2025 (formerly 115BAA): 22% + 10% surcharge + 4% cess = 25.168%; MAT not applicable. | I10: Confirm with a CA: loss carry-forward (8 yrs), any startup holiday eligibility, GST treatment.
A11: Employer on-cost over CTC (PF, gratuity, insurance) | B11: % of CTC | C11: =IF(D11="",E11,CHOOSE($C$3,D11,E11,F11)) -> 0.12 | E11: 0.12 | G11: Assumption | H11: Typical Indian employer statutory and benefit load; varies by salary structure.
A12: Annual salary increment | B12: % p.a. | C12: =IF(D12="",E12,CHOOSE($C$3,D12,E12,F12)) -> 0.08 | E12: 0.08 | G12: Assumption | H12: Mid-range Indian tech increment assumption.
A13: Non-people cost inflation | B13: % p.a. | C13: =IF(D13="",E13,CHOOSE($C$3,D13,E13,F13)) -> 0.05 | E13: 0.05 | G13: Assumption | H13: Approximates Indian CPI plus vendor price drift.
A14: Discount rate for LTV | B14: % p.a. | C14: =IF(D14="",E14,CHOOSE($C$3,D14,E14,F14)) -> 0.2 | E14: 0.2 | G14: Assumption | H14: Early-stage cost of capital proxy; not a WACC estimate.
A15: Maximum customer life used in LTV | B15: years | C15: =IF(D15="",E15,CHOOSE($C$3,D15,E15,F15)) -> 7 | E15: 7 | G15: Assumption | H15: Caps LTV so low churn cannot imply a near-perpetual customer.
A17: B. SALES CAPACITY & FUNNEL
A18: Month first account executive (AE) joins in FY27 | B18: month of FY | C18: =IF(D18="",E18,CHOOSE($C$3,D18,E18,F18)) -> 4 | E18: 4 | G18: Assumption | H18: Seed closes before sales hiring; founders sell alone until then.
A19: AE ramp to full productivity | B19: months | C19: =IF(D19="",E19,CHOOSE($C$3,D19,E19,F19)) -> 6 | D19: 6 | E19: 6 | F19: 4 | G19: Assumption | H19: Complex industrial B2B sale; new reps need plant/OT credibility.
A20: Founder selling capacity, FY27-FY28 | B20: AE equivalents | C20: =IF(D20="",E20,CHOOSE($C$3,D20,E20,F20)) -> 0.5 | E20: 0.5 | G20: Assumption | H20: Founder-led sales in early stage.
A21: Founder selling capacity, FY29+ | B21: AE equivalents | C21: =IF(D21="",E21,CHOOSE($C$3,D21,E21,F21)) -> 0.25 | E21: 0.25 | G21: Assumption | H21: Founder shifts to enterprise accounts and fundraising.
A22: Qualified opportunities per ramped AE per month | B22: # | C22: =IF(D22="",E22,CHOOSE($C$3,D22,E22,F22)) -> 3 | D22: 2 | E22: 3 | F22: 4 | G22: Validate | H22: No India-specific benchmark found. Qualified = plant visit done, data-readiness confirmed, decision maker engaged. | I22: Track in first 6 months of selling; this is the single largest volume driver.
A23: Lead to qualified opportunity | B23: % | C23: =IF(D23="",E23,CHOOSE($C$3,D23,E23,F23)) -> 0.2 | E23: 0.2 | G23: Assumption | H23: Used only to back-solve lead and account volumes.
A24: Target account to engaged lead | B24: % | C24: =IF(D24="",E24,CHOOSE($C$3,D24,E24,F24)) -> 0.25 | E24: 0.25 | G24: Assumption | H24: Used only to back-solve target-account list size.
A25: Opportunity to pilot (direct) | B25: % | C25: =IF(D25="",E25,CHOOSE($C$3,D25,E25,F25)) -> 0.3 | D25: 0.25 | E25: 0.3 | F25: 0.35 | G25: Validate | H25: Assumption; plants often want proof on their own machines before buying. | I25: Pilot design and acceptance criteria must be tested in interviews.
A26: Opportunity to pilot (partner-sourced) | B26: % | C26: =IF(D26="",E26,CHOOSE($C$3,D26,E26,F26)) -> 0.35 | D26: 0.3 | E26: 0.35 | F26: 0.4 | G26: Assumption | H26: Partner referral carries trust; modestly higher than direct.
A27: Sales cycle: qualified opportunity to pilot start | B27: months | C27: =IF(D27="",E27,CHOOSE($C$3,D27,E27,F27)) -> 3 | D27: 4 | E27: 3 | F27: 2 | G27: Validate | H27: Mid-market capex and IT approvals; total opp-to-go-live = this + pilot + implementation. | I27: Measure on first 10 opportunities.
A28: Paid pilot duration | B28: months | C28: =IF(D28="",E28,CHOOSE($C$3,D28,E28,F28)) -> 3 | E28: 3 | G28: Assumption | H28: Long enough to observe disruption events on critical machines.
A29: Pilot to paid annual contract | B29: % | C29: =IF(D29="",E29,CHOOSE($C$3,D29,E29,F29)) -> 0.55 | D29: 0.4 | E29: 0.55 | F29: 0.65 | G29: Validate | H29: Assumption. Industrial pilots frequently stall ('pilot purgatory'). | I29: Critical: define success metrics before each pilot.
A30: Partner channel productivity multiplier | B30: x plan | C30: =IF(D30="",E30,CHOOSE($C$3,D30,E30,F30)) -> 1 | D30: 0.5 | E30: 1 | F30: 1.5 | G30: Assumption | H30: Scales the partner opportunity plan in section H.
A32: C. IMPLEMENTATION & DEPLOYMENT
A33: Contract signature to go-live (implementation time) | B33: months | C33: =IF(D33="",E33,CHOOSE($C$3,D33,E33,F33)) -> 2 | D33: 3 | E33: 2 | F33: 2 | G33: Assumption | H33: PlanetTogether states many APS integrations take 4-8 weeks; plants with poor data take longer.
A34: Concurrent implementations per implementation engineer | B34: # | C34: =IF(D34="",E34,CHOOSE($C$3,D34,E34,F34)) -> 3 | D34: 2 | E34: 3 | F34: 3.5 | G34: Assumption | H34: REVISED from 2 (bear 1.5 / bull 2.5). Partner-led delivery: SI partners do on-site wiring; our engineers configure remotely from a standard connector library, so each runs 3 at once. The partner's fee is in the direct cost per go-live (row 38).
A35: Engineer load of one active pilot vs one implementation | B35: x | C35: =IF(D35="",E35,CHOOSE($C$3,D35,E35,F35)) -> 0.5 | E35: 0.5 | G35: Assumption | H35: Pilots use a lighter, time-boxed scope.
A36: Month implementation team starts | B36: month # | C36: =IF(D36="",E36,CHOOSE($C$3,D36,E36,F36)) -> 3 | E36: 3 | G36: Assumption | H36: First hire with seed money.
A37: Minimum implementation engineers once started | B37: # | C37: =IF(D37="",E37,CHOOSE($C$3,D37,E37,F37)) -> 1 | E37: 1 | G37: Assumption
A38: Direct cost per go-live (travel, on-site, connectors, integration tooling) | B38: ₹ lakh | C38: =IF(D38="",E38,CHOOSE($C$3,D38,E38,F38)) -> 2.5 | E38: 2.5 | G38: Assumption | H38: REVISED from ₹1.5 lakh. Now includes ~₹1 lakh paid to the SI partner per site (wiring, gateway set-up) plus travel and connectors. Excludes our engineer salaries (modelled separately). | I38: Cost a real implementation end to end.
A39: Implementation direct-cost multiplier | B39: x | C39: =IF(D39="",E39,CHOOSE($C$3,D39,E39,F39)) -> 1 | D39: 1.3 | E39: 1 | F39: 0.85 | G39: Assumption | H39: Bear reflects customisation creep.
A40: Direct cost per pilot started | B40: ₹ lakh | C40: =IF(D40="",E40,CHOOSE($C$3,D40,E40,F40)) -> 1 | E40: 1 | G40: Assumption | H40: Site visits, temporary data connections.
A41: Share of new plants needing the optional IoT kit | B41: % | C41: =IF(D41="",E41,CHOOSE($C$3,D41,E41,F41)) -> 0.5 | D41: 0.6 | E41: 0.5 | F41: 0.4 | G41: Validate | H41: Software-first: kit only where PLC/CNC data cannot be read. | I41: Survey data-readiness of target plants.
A42: Critical machines connected per plant (average) | B42: # | C42: =IF(D42="",E42,CHOOSE($C$3,D42,E42,F42)) -> 20 | E42: 20 | G42: Assumption | H42: Between Essential (≤15) and Professional (≤30) coverage.
A43: IoT kit cost per plant (sensors + gateway, ~12 machines) | B43: ₹ lakh | C43: =IF(D43="",E43,CHOOSE($C$3,D43,E43,F43)) -> 3.5 | E43: 3.5 | G43: Assumption | H43: Benchmark: non-intrusive sensors typically $200-600 per machine (TeepTrak 2026). 12 x ~$300 x ₹95 = ₹3.4 lakh incl. gateway.
A44: Markup on resold IoT kit | B44: % | C44: =IF(D44="",E44,CHOOSE($C$3,D44,E44,F44)) -> 0.1 | E44: 0.1 | G44: Assumption | H44: Pass-through with handling margin; not a profit engine.
...

Sheet 2_Market
A1: 2. MARKET SIZING: TAM, SAM, SOM (revised 11-Oct-2026: TAM = 63,728 operating factories in 7 target industries, ASI 2023-24)
A2: TAM is the broad industry pool, not the qualified customer base. SAM applies size, geography and readiness filters once each (section F). SOM is the Year-5 live-plant outcome of the sales-capacity engine, solved to the bear / base / bull targets.
A4: A. SEGMENT PLANT COUNTS: CROSS-CHECK AND SIZE MIX (ASI 2019-20 by NIC, scaled; the TAM itself now uses ASI 2023-24, section F)
A5: Segment (NIC-2008 2-digit) | B5: Role | C5: Factories in operation ASI 2019-20 | D5: Persons engaged ASI 2019-20 | E5: Avg persons per factory | F5: Share with 100+ workers, est. | G5: Factories 2024-25 (scaled) | H5: Plants with 100+ workers 2024-25, est. | I5: Notes
A6: 29 Motor vehicles, trailers (incl. auto components) | B6: SAM | C6: 5353 | D6: 1082076 | E6: =D6/C6 -> 202.14384 | F6: =MIN($C$24,$C$23*E6/$C$22) -> 0.48304529 | G6: =C6*$C$26 -> 5889.7068 | H6: =G6*F6 -> 2844.9951 | I6: Beachhead. Large plants.
A7: 28 Machinery & equipment n.e.c. | B7: SAM | C7: 10949 | D7: 935811 | E7: =D7/C7 -> 85.469997 | F7: =MIN($C$24,$C$23*E7/$C$22) -> 0.2042401 | G7: =C7*$C$26 -> 12046.777 | H7: =G7*F7 -> 2460.4351 | I7: Core.
A8: 25 Fabricated metal products | B8: SAM | C8: 12635 | D8: 705038 | E8: =D8/C8 -> 55.800396 | F8: =MIN($C$24,$C$23*E8/$C$22) -> 0.13334128 | G8: =C8*$C$26 -> 13901.821 | H8: =G8*F8 -> 1853.6865 | I8: Core.
A9: 24 Basic metals (castings, forgings, steel processing) | B9: SAM | C9: 10106 | D9: 1204877 | E9: =D9/C9 -> 119.22393 | F9: =MIN($C$24,$C$23*E9/$C$22) -> 0.28489889 | G9: =C9*$C$26 -> 11119.256 | H9: =G9*F9 -> 3167.8636 | I9: ADDED: furnaces, presses and casting lines that feed auto and machinery supply chains.
A10: 22 Rubber & plastics products | B10: SAM | C10: 11732 | D10: 843562 | E10: =D10/C10 -> 71.902659 | F10: =MIN($C$24,$C$23*E10/$C$22) -> 0.17181943 | G10: =C10*$C$26 -> 12908.283 | H10: =G10*F10 -> 2217.8939 | I10: MOVED from adjacent to SAM: injection-moulding cells have the same machine-and-schedule problem.
A11: 27 Electrical equipment | B11: SAM | C11: 6076 | D11: 635006 | E11: =D11/C11 -> 104.51053 | F11: =MIN($C$24,$C$23*E11/$C$22) -> 0.24973959 | G11: =C11*$C$26 -> 6685.1968 | H11: =G11*F11 -> 1669.5583 | I11: MOVED from adjacent to SAM: machining and assembly lines.
A12: 30 Other transport equipment | B12: SAM | C12: 1855 | D12: 421386 | E12: =D12/C12 -> 227.16226 | F12: =MIN($C$24,$C$23*E12/$C$22) -> 0.5 | G12: =C12*$C$26 -> 2040.9875 | H12: =G12*F12 -> 1020.4937 | I12: ADDED: two-wheeler, rail and aerospace component plants.
A13: 13 Textiles | B13: TAM only | C13: 13539 | D13: 1629101 | E13: =D13/C13 -> 120.32654 | F13: =MIN($C$24,$C$23*E13/$C$22) -> 0.2875337 | G13: =C13*$C$26 -> 14896.458 | H13: =G13*F13 -> 4283.2337 | I13: Machine-intensive but continuous spinning and weaving; different scheduling logic.
A14: 26 Computer, electronic & optical products | B14: TAM only | C14: 1908 | D14: 283470 | E14: =D14/C14 -> 148.56918 | F14: =MIN($C$24,$C$23*E14/$C$22) -> 0.35502265 | G14: =C14*$C$26 -> 2099.3014 | H14: =G14*F14 -> 745.29956 | I14: Assembly-led; outside the current product.
A15: Target industries (7) | C15: =SUMIF($B$6:$B$14,"SAM",C6:C14) -> 58706 | D15: =SUMIF($B$6:$B$14,"SAM",D6:D14) -> 5827756 | G15: =SUMIF($B$6:$B$14,"SAM",G6:G14) -> 64592.028 | H15: =SUMIF($B$6:$B$14,"SAM",H6:H14) -> 15234.926 | I15: Counts are from ASI 2019-20 (latest NIC-wise table found) scaled to the 2024-25 factory total.
A16: Machine-intensive segments (9) | C16: =SUM(C6:C14) -> 74153 | D16: =SUM(D6:D14) -> 7740327 | G16: =SUM(G6:G14) -> 81587.788 | H16: =SUM(H6:H14) -> 20263.46
A18: B. PARAMETERS
A19: Parameter | B19: Unit | C19: Value | D19: Type | E19: Source / rationale
A20: All-India factories in operation, ASI 2019-20 | B20: # | C20: 198628 | D20: Verified fact | E20: Lok Sabha Unstarred Q.541 (6-Dec-2023), MoSPI annexure.
A21: All-India persons engaged, ASI 2019-20 | B21: # | C21: 16624291 | D21: Verified fact | E21: Lok Sabha Unstarred Q.541 (6-Dec-2023), MoSPI annexure.
A22: All-India average persons per factory | B22: # | C22: =C21/C20 -> 83.695607 | D22: Calculated
A23: Share of all factories with 100+ workers | B23: % | C23: 0.2 | D23: Verified fact (rounded) | E23: 'About one in five' operational factories employed 100+ workers (ASI 2022-23, via Data For India). Workers are fewer than persons engaged, so this is conservative. Replaces the ASI 2008-09 figure (14.1% for 100-999 persons) used before.
A24: Cap on any segment's 100+ share | B24: % | C24: 0.5 | D24: Assumption | E24: Stops the size-scaling method overshooting in large-plant segments (binds only for NIC 30 at current inputs).
A25: All-India factories in operation, ASI 2024-25 | B25: # | C25: 218543 | D25: Verified fact | E25: MoSPI press note and factsheet, ASI 2024-25 (2,18,543 in operation; 2,66,931 total).
A26: Scaling factor 2019-20 → 2024-25 | B26: x | C26: =C25/C20 -> 1.1002628 | D26: Assumption | E26: Assumes each segment grew in line with all manufacturing.
A27: Technical readiness (machine data readable or kit acceptable; planner exists) | B27: % | C27: 0.4 | D27: Validate | E27: Unchanged from the original model. No published source; survey 30+ target plants.
A28: Share of factories in the top-5 manufacturing states | B28: % | C28: 0.533 | D28: Verified fact | E28: Tamil Nadu, Gujarat, Maharashtra, Uttar Pradesh and Karnataka hold 53.3% of establishments (ASI 2024-25 press note). Direct sales cover these; partner reach beyond them is not counted.
A30: C. TAM / SAM / SOM
A31: Measure | B31: Unit | C31: Plants | D31: ₹ lakh per plant p.a. | E31: Market ₹ lakh p.a. | F31: Market ₹ crore p.a. | I31: Definition
A32: TAM: 7 target industries, operating factories (ASI 2023-24): broad industry pool, not qualified customers | C32: =D56 -> 63728 | D32: =3_Pricing!$F$8 -> 28.75 | E32: =C32*D32 -> 1832180 | F32: =E32/100 -> 18321.8 | I32: Pool × active scenario's blended realised price. Overstates value: most of these plants are too small for this pricing.
A33: Size-qualified pool: 100+ workers | C33: =D58 -> 15031.133 | D33: =3_Pricing!$F$8 -> 28.75 | E33: =C33*D33 -> 432145.08 | F33: =E33/100 -> 4321.4508 | I33: After filter 2 (section F).
A34: SAM: × top-5 states × operational readiness | C34: =D61 -> 3204.6376 | D34: =3_Pricing!$F$8 -> 28.75 | E34: =C34*D34 -> 92133.332 | F34: =E34/100 -> 921.33332 | I34: After filters 3 and 4 (section F). Filters 2-4 are estimates or unvalidated.
A35: SOM FY31: live paying plants (engine, active scenario; solved to the scenario target) | C35: =INDEX(Engine_Monthly!$D$49:$BK$49,1,5*12) -> 400.00001 | D35: =4_Revenue_Build!G34 -> 39.364444 | E35: =C35*D35 -> 15745.778 | F35: =E35/100 -> 157.45778 | I35: From AEs, partners, conversion, implementation capacity and churn. Not a share assumption.
A36: SOM FY31 as % of SAM plants | C36: =IFERROR(C35/C34,0) -> 0.12481911 | I36: Low single digits five years in: room to grow without new segments.
A37: SOM FY36: implied live plants (valuation fade) | C37: =14_Valuation!C87 -> 388.30242 | D37: =14_Valuation!C89 -> 50.240114 | E37: =C37*D37 -> 19508.358 | F37: =E37/100 -> 195.08358 | I37: FY36 subscription revenue ÷ ARR per plant grown at list-price escalation. A ceiling check on the fade, not a driver.
A38: SOM FY36 as % of SAM plants | C38: =IFERROR(C37/C34,0) -> 0.1211689 | I38: Against today’s SAM, which itself grows with the factory count. Above ~25% would make the fade implausible.
A39: TAM and SAM are valued at the FY27 blended list price; SOM at FY31 / FY36 ARR per plant, which includes price escalation and expansion. Compare shares on plant counts.
A40: D. RECONCILIATION WITH THE SALES FORECAST
A41: Qualified opportunities generated over 5 years | C41: =SUM(Engine_Monthly!$D$20:$BK$20) -> 3570.1908
A42: …as % of SAM plants | C42: =IFERROR(C41/C34,0) -> 1.11407 | I42: Below 100% means the funnel can be fed from SAM plants alone (re-engagements counted).
A43: Target-account engagements over 5 years (back-solved; repeat touches counted) | C43: =SUM(Engine_Monthly!$D$22:$BK$22) -> 71403.815
...

Sheet 3_Pricing
A1: 3. BUSINESS MODEL & PRICING (tier prices are hypotheses to validate; revised 11-Oct-2026)
A3: Pricing tiers (per plant, annual subscription)
A4: Attribute | C4: Starter | D4: Professional | E4: Enterprise | F4: Blended (new-customer mix) | G4: Notes
A5: Target customer | C5: Single-line plant (~₹100-250 crore revenue), 10-15 critical machines. Hypothesis. | D5: Mid-sized plant (~₹250-500 crore revenue), 15-30 critical machines, planner in place. Hypothesis. | E5: ₹500 crore+ plant or multi-plant group, ERP/MES integration expected. Hypothesis.
A6: Included functionality | C6: Machine-health risk alerts, downtime capture, disruption log, basic dashboards | D6: Starter + constraint-aware disruption scenarios, ranked recommendations with ₹ trade-offs, approval workflow | E6: Professional + ERP/MES integration, multi-line optimisation, group reporting, SSO, SLA
A7: Coverage | C7: Up to 15 critical machines, 1 line | D7: Up to 30 critical machines, up to 3 lines | E7: Unlimited lines in a plant; group pricing per plant
A8: Average realised annual subscription per plant (₹ lakh, FY27; active scenario, from row 51-53) | C8: =INDEX(C$51:C$53,Inputs!$C$3,1) -> 15 | D8: =INDEX(D$51:D$53,Inputs!$C$3,1) -> 30 | E8: =INDEX(E$51:E$53,Inputs!$C$3,1) -> 50 | F8: =SUMPRODUCT($C$11:$E$11,C8:E8) -> 28.75 | G8: REVISED from 4.8 / 9.6 / 18.0. Professional = ₹95k a month, equal to PlanetTogether's Essential APS listing ($1,000/plant/month ≈ ₹11.4 lakh a year at ₹95/$) and inside the 3x value rule on 9_Customer_ROI (3.05x; customer payback ≈ 13 months). Benefits there are in today's ₹, so the test holds over time if they rise with wages and input costs at the 5% list-price escalation. Enterprise = 2x Professional for multi-line plants and groups.
A9: Monthly equivalent (₹ lakh) | C9: =C8/12 -> 1.25 | D9: =D8/12 -> 2.5 | E9: =E8/12 -> 4.1666667
A10: One-time implementation fee (₹ lakh) | C10: 3 | D10: 6 | E10: 12 | F10: =SUMPRODUCT($C$11:$E$11,C10:E10) -> 6.15 | G10: REVISED from 1.5 / 4 / 8. Priced to recover deployment cost including SI partner fees, at roughly an IT-services margin; ≈0.5x first-year ACV, usual for software that connects to PLC/CNC data.
A11: Share of new customers by tier (active scenario, from rows 54-56) | C11: =INDEX(C$54:C$56,Inputs!$C$3,1) -> 0.35 | D11: =INDEX(D$54:D$56,Inputs!$C$3,1) -> 0.45 | E11: =INDEX(E$54:E$56,Inputs!$C$3,1) -> 0.2 | F11: =SUM(C11:E11) -> 1 | G11: REVISED from 40 / 45 / 15. Focus on the ₹100-500 crore plants in the problem statement. Validate in the first 20 deals.
A12: Cloud/AI load vs average plant | C12: 0.6 | D12: 1 | E12: 1.8 | G12: Relative data volume and solver usage.
A13: Support load vs average plant | C13: 0.7 | D13: 1 | E13: 1.6
A14: Recurring cost to serve per plant (₹ lakh p.a., FY27) | C14: =(Inputs!$C$55+Inputs!$C$56+Inputs!$C$57+Inputs!$C$58+Inputs!$C$59)*12*C12+(Inputs!$C$75/Inputs!$C$64+Inputs!$C$76/Inputs!$C$65)*(1+Inputs!$C$11)*C13 -> 1.66304 | D14: =(Inputs!$C$55+Inputs!$C$56+Inputs!$C$57+Inputs!$C$58+Inputs!$C$59)*12*D12+(Inputs!$C$75/Inputs!$C$64+Inputs!$C$76/Inputs!$C$65)*(1+Inputs!$C$11)*D13 -> 2.6672 | E14: =(Inputs!$C$55+Inputs!$C$56+Inputs!$C$57+Inputs!$C$58+Inputs!$C$59)*12*E12+(Inputs!$C$75/Inputs!$C$64+Inputs!$C$76/Inputs!$C$65)*(1+Inputs!$C$11)*E13 -> 4.67552 | F14: =SUMPRODUCT($C$11:$E$11,C14:E14) -> 2.717408 | G14: Cloud, AI, data, licences, monitoring + allocated customer success & support. Excludes shared fixed platform cost.
A15: Expected SaaS gross margin per tier | C15: =IFERROR(1-C14/C8,0) -> 0.88913067 | D15: =IFERROR(1-D14/D8,0) -> 0.91109333 | E15: =IFERROR(1-E14/E8,0) -> 0.9064896 | F15: =IFERROR(1-F14/F8,0) -> 0.90548146 | G15: Before shared platform cost. Essential is thin: the tier exists to land, not to earn.
A16: Support requirements | C16: Business-hours remote support; quarterly review | D16: Named CSM; monthly value review; shift-hour support | E16: Dedicated CSM; SLA; quarterly executive review
A17: Upselling path | C17: Upgrade to Professional once alerts prove reliable | D17: Add lines/machines; move to Enterprise for ERP sync | E17: Roll out to sister plants; group contract
A18: Mix check (must equal 100%) | C18: =IF(ABS(F11-1)<0.0001,"OK","MIX ≠ 100%") -> OK
A20: Other revenue streams evaluated
A21: Stream | C21: In model? | D21: How modelled | G21: Why
A22: Annual SaaS subscription per plant | C22: Yes | D22: ARR per live plant by tier | G22: Core recurring revenue; only this counts in ARR.
A23: One-time implementation & integration fee | C23: Yes | D23: Recognised at go-live | G23: Excluded from ARR. Priced to recover deployment cost, including SI partner fees, at about an IT-services margin (≈40% services gross margin, 5_Cost_of_Service).
A24: Paid pilots | C24: Yes | D24: Recognised over pilot months | G24: Paid pilots filter serious buyers. Not ARR.
A25: Machine / line add-ons | C25: Partly | D25: Inside expansion % of ARR | G25: Captured as upsell rather than a separate meter, to keep pricing simple.
A26: Premium analytics modules | C26: Partly | D26: Inside expansion % of ARR | G26: Not specified until core product is proven.
A27: Multi-plant enterprise contracts | C27: Partly | D27: Enterprise tier + enterprise account managers | G27: Upside once a group adopts at one plant.
A28: Gain-share (performance-linked) fee | C28: Yes, haircut | D28: Inputs section K; zero in bear | G28: Separate revenue line; never in ARR; expected value after a collection haircut.
A29: IoT kit resale | C29: Yes | D29: Other operating revenue at go-live | G29: Pass-through at 10% markup; only for plants without readable machine data.
A31: Pricing unit: which structure fits mid-sized Indian plants?
A32: Structure | C32: For | D32: Against | E32: Fit | G32: Verdict
A33: Per plant (flat) | C33: Simple budget line; easy to approve | D33: Under-charges large plants, over-charges small ones | E33: Medium | G33: Use as the platform base.
A34: Per machine | C34: Scales with value; common in OEE tools ($30-150/machine/month) | D34: Buyers limit coverage to save money, which weakens the optimiser | E34: Low | G34: Avoid as the primary meter.
A35: Per production line | C35: Matches how plants think about capacity | D35: Line definitions vary; hard to audit | E35: Medium | G35: Use as a tier boundary only.
A36: Hybrid: per-plant tier with machine/line bands | C36: Predictable price; still scales with plant size | D36: Needs clear band rules | E36: High | G36: RECOMMENDED
A38: Price benchmarks (context only; products are not directly comparable)
A39: Benchmark | C39: Published price | D39: Unit | E39: ₹ lakh per year (converted) | F39: Source type | G39: Comparability
A40: OEE / production monitoring software (market range) | C40: $30-150 | D40: per machine per month | E40: =30*12*Inputs!$C$9/100000*20 -> 6.84 | F40: Vendor blog (TeepTrak, Aug 2026) | G40: ₹ figure = low end x 20 machines. Monitoring only, no optimisation.
A41: OEE software, mid-market tier | C41: $200-450 | D41: per machine per month | E41: =200*12*Inputs!$C$9/100000*20 -> 45.6 | F41: Vendor blog (Fabrico 2026) | G41: ₹ figure = low end x 20 machines. Western pricing; Indian buyers will push lower.
A42: OEE site licence | C42: $1,500-8,000 | D42: per site per month | E42: =1500*12*Inputs!$C$9/100000 -> 17.1 | F42: Vendor blog (Fabrico 2026) | G42: ₹ figure = low end.
A43: PlanetTogether Essential APS | C43: $1,000 | D43: per plant per month, billed annually | E43: =1000*12*Inputs!$C$9/100000 -> 11.4 | F43: Third-party listing (FitGap) | G43: Scheduling only; closest analogue to the Professional tier.
A44: Siemens Opcenter APS | C44: from $20,000 | D44: per organisation licence + 18-22% maintenance | E44: =20000*Inputs!$C$9/100000 -> 19 | F44: Third-party estimate (ITQlick) | G44: Perpetual licence; enterprise buyer.
...

Sheet 4_Revenue_Build
A1: 4. CUSTOMER ACQUISITION & REVENUE BUILD (annual view of the monthly engine)
A2: Funnel → pilots → contracts → implementation → go-live → billing. Pilots are never counted as paying customers or ARR.
A3: ₹ lakh | B3: Unit | C3: =INDEX(Engine_Monthly!$D$10:$BK$10,1,12) -> FY27 | D3: =INDEX(Engine_Monthly!$D$10:$BK$10,1,24) -> FY28 | E3: =INDEX(Engine_Monthly!$D$10:$BK$10,1,36) -> FY29 | F3: =INDEX(Engine_Monthly!$D$10:$BK$10,1,48) -> FY30 | G3: =INDEX(Engine_Monthly!$D$10:$BK$10,1,60) -> FY31
A4: Fiscal-year index | C4: 1 | D4: 2 | E4: 3 | F4: 4 | G4: 5
A6: FUNNEL
A7: Target accounts engaged (back-solved) | B7: # | C7: =SUMIF(Engine_Monthly!$D$7:$BK$7,C$4,Engine_Monthly!$D$22:$BK$22) -> 750 | D7: =SUMIF(Engine_Monthly!$D$7:$BK$7,D$4,Engine_Monthly!$D$22:$BK$22) -> 4809.6134 | E7: =SUMIF(Engine_Monthly!$D$7:$BK$7,E$4,Engine_Monthly!$D$22:$BK$22) -> 12538.84 | F7: =SUMIF(Engine_Monthly!$D$7:$BK$7,F$4,Engine_Monthly!$D$22:$BK$22) -> 22038.067 | G7: =SUMIF(Engine_Monthly!$D$7:$BK$7,G$4,Engine_Monthly!$D$22:$BK$22) -> 31267.294
A8: Leads generated (back-solved) | B8: # | C8: =SUMIF(Engine_Monthly!$D$7:$BK$7,C$4,Engine_Monthly!$D$21:$BK$21) -> 187.5 | D8: =SUMIF(Engine_Monthly!$D$7:$BK$7,D$4,Engine_Monthly!$D$21:$BK$21) -> 1202.4034 | E8: =SUMIF(Engine_Monthly!$D$7:$BK$7,E$4,Engine_Monthly!$D$21:$BK$21) -> 3134.7101 | F8: =SUMIF(Engine_Monthly!$D$7:$BK$7,F$4,Engine_Monthly!$D$21:$BK$21) -> 5509.5168 | G8: =SUMIF(Engine_Monthly!$D$7:$BK$7,G$4,Engine_Monthly!$D$21:$BK$21) -> 7816.8235
A9: Qualified opportunities | B9: # | C9: =SUMIF(Engine_Monthly!$D$7:$BK$7,C$4,Engine_Monthly!$D$20:$BK$20) -> 37.5 | D9: =SUMIF(Engine_Monthly!$D$7:$BK$7,D$4,Engine_Monthly!$D$20:$BK$20) -> 240.48067 | E9: =SUMIF(Engine_Monthly!$D$7:$BK$7,E$4,Engine_Monthly!$D$20:$BK$20) -> 626.94202 | F9: =SUMIF(Engine_Monthly!$D$7:$BK$7,F$4,Engine_Monthly!$D$20:$BK$20) -> 1101.9034 | G9: =SUMIF(Engine_Monthly!$D$7:$BK$7,G$4,Engine_Monthly!$D$20:$BK$20) -> 1563.3647
A10: of which partner-sourced | B10: # | C10: =SUMIF(Engine_Monthly!$D$7:$BK$7,C$4,Engine_Monthly!$D$19:$BK$19) -> 0 | D10: =SUMIF(Engine_Monthly!$D$7:$BK$7,D$4,Engine_Monthly!$D$19:$BK$19) -> 100.98067 | E10: =SUMIF(Engine_Monthly!$D$7:$BK$7,E$4,Engine_Monthly!$D$19:$BK$19) -> 302.94202 | F10: =SUMIF(Engine_Monthly!$D$7:$BK$7,F$4,Engine_Monthly!$D$19:$BK$19) -> 504.90336 | G10: =SUMIF(Engine_Monthly!$D$7:$BK$7,G$4,Engine_Monthly!$D$19:$BK$19) -> 706.8647
A11: Paid pilots started | B11: # | C11: =SUMIF(Engine_Monthly!$D$7:$BK$7,C$4,Engine_Monthly!$D$26:$BK$26) -> 7.2 | D11: =SUMIF(Engine_Monthly!$D$7:$BK$7,D$4,Engine_Monthly!$D$26:$BK$26) -> 60.257426 | E11: =SUMIF(Engine_Monthly!$D$7:$BK$7,E$4,Engine_Monthly!$D$26:$BK$26) -> 170.03309 | F11: =SUMIF(Engine_Monthly!$D$7:$BK$7,F$4,Engine_Monthly!$D$26:$BK$26) -> 316.54456 | G11: =SUMIF(Engine_Monthly!$D$7:$BK$7,G$4,Engine_Monthly!$D$26:$BK$26) -> 467.78103
A12: Active pilots at year end (not customers) | B12: # | C12: =INDEX(Engine_Monthly!$D$28:$BK$28,1,C$4*12) -> 3.6 | D12: =INDEX(Engine_Monthly!$D$28:$BK$28,1,D$4*12) -> 20.985809 | E12: =INDEX(Engine_Monthly!$D$28:$BK$28,1,E$4*12) -> 54.182426 | F12: =INDEX(Engine_Monthly!$D$28:$BK$28,1,F$4*12) -> 93.454044 | G12: =INDEX(Engine_Monthly!$D$28:$BK$28,1,G$4*12) -> 130.02566
A13: Commercial contracts signed (new paying customers) | B13: # | C13: =SUMIF(Engine_Monthly!$D$7:$BK$7,C$4,Engine_Monthly!$D$32:$BK$32) -> 1.98 | D13: =SUMIF(Engine_Monthly!$D$7:$BK$7,D$4,Engine_Monthly!$D$32:$BK$32) -> 23.57939 | E13: =SUMIF(Engine_Monthly!$D$7:$BK$7,E$4,Engine_Monthly!$D$32:$BK$32) -> 75.260059 | F13: =SUMIF(Engine_Monthly!$D$7:$BK$7,F$4,Engine_Monthly!$D$32:$BK$32) -> 152.50012 | G13: =SUMIF(Engine_Monthly!$D$7:$BK$7,G$4,Engine_Monthly!$D$32:$BK$32) -> 237.16518
A14: of which partner-sourced | B14: # | C14: =SUMIF(Engine_Monthly!$D$7:$BK$7,C$4,Engine_Monthly!$D$31:$BK$31) -> 0 | D14: =SUMIF(Engine_Monthly!$D$7:$BK$7,D$4,Engine_Monthly!$D$31:$BK$31) -> 9.7193897 | E14: =SUMIF(Engine_Monthly!$D$7:$BK$7,E$4,Engine_Monthly!$D$31:$BK$31) -> 38.877559 | F14: =SUMIF(Engine_Monthly!$D$7:$BK$7,F$4,Engine_Monthly!$D$31:$BK$31) -> 77.755117 | G14: =SUMIF(Engine_Monthly!$D$7:$BK$7,G$4,Engine_Monthly!$D$31:$BK$31) -> 116.63268
A15: Opportunity-to-go-live elapsed time | B15: months | C15: =Inputs!$C$27+Inputs!$C$126+Inputs!$C$28+Inputs!$C$33 -> 8 | D15: =Inputs!$C$27+Inputs!$C$126+Inputs!$C$28+Inputs!$C$33 -> 8 | E15: =Inputs!$C$27+Inputs!$C$126+Inputs!$C$28+Inputs!$C$33 -> 8 | F15: =Inputs!$C$27+Inputs!$C$126+Inputs!$C$28+Inputs!$C$33 -> 8 | G15: =Inputs!$C$27+Inputs!$C$126+Inputs!$C$28+Inputs!$C$33 -> 8 | H15: Sales cycle + pilot + implementation. The cash cost of this lag is why revenue trails hiring.
A17: DEPLOYMENT & CUSTOMERS
A18: Plants gone live | B18: # | C18: =SUMIF(Engine_Monthly!$D$7:$BK$7,C$4,Engine_Monthly!$D$42:$BK$42) -> 1.0725 | D18: =SUMIF(Engine_Monthly!$D$7:$BK$7,D$4,Engine_Monthly!$D$42:$BK$42) -> 17.039593 | E18: =SUMIF(Engine_Monthly!$D$7:$BK$7,E$4,Engine_Monthly!$D$42:$BK$42) -> 63.335466 | F18: =SUMIF(Engine_Monthly!$D$7:$BK$7,F$4,Engine_Monthly!$D$42:$BK$42) -> 138.26552 | G18: =SUMIF(Engine_Monthly!$D$7:$BK$7,G$4,Engine_Monthly!$D$42:$BK$42) -> 223.67308
A19: Implementation backlog at year end | B19: # | C19: =INDEX(Engine_Monthly!$D$43:$BK$43,1,C$4*12) -> 0 | D19: =INDEX(Engine_Monthly!$D$43:$BK$43,1,D$4*12) -> 0 | E19: =INDEX(Engine_Monthly!$D$43:$BK$43,1,E$4*12) -> 0 | F19: =INDEX(Engine_Monthly!$D$43:$BK$43,1,F$4*12) -> 0 | G19: =INDEX(Engine_Monthly!$D$43:$BK$43,1,G$4*12) -> 0 | H19: Non-zero means deployment capacity is binding.
A20: Plants churned | B20: # | C20: =SUMIF(Engine_Monthly!$D$7:$BK$7,C$4,Engine_Monthly!$D$48:$BK$48) -> 0.011564652 | D20: =SUMIF(Engine_Monthly!$D$7:$BK$7,D$4,Engine_Monthly!$D$48:$BK$48) -> 0.50193751 | E20: =SUMIF(Engine_Monthly!$D$7:$BK$7,E$4,Engine_Monthly!$D$48:$BK$48) -> 3.6844616 | F20: =SUMIF(Engine_Monthly!$D$7:$BK$7,F$4,Engine_Monthly!$D$48:$BK$48) -> 12.115088 | G20: =SUMIF(Engine_Monthly!$D$7:$BK$7,G$4,Engine_Monthly!$D$48:$BK$48) -> 27.073106
A21: Live paying plants at year end | B21: # | C21: =INDEX(Engine_Monthly!$D$49:$BK$49,1,C$4*12) -> 1.0609353 | D21: =INDEX(Engine_Monthly!$D$49:$BK$49,1,D$4*12) -> 17.598591 | E21: =INDEX(Engine_Monthly!$D$49:$BK$49,1,E$4*12) -> 77.249595 | F21: =INDEX(Engine_Monthly!$D$49:$BK$49,1,F$4*12) -> 203.40003 | G21: =INDEX(Engine_Monthly!$D$49:$BK$49,1,G$4*12) -> 400.00001
A22: Average live paying plants | B22: # | C22: =AVERAGEIF(Engine_Monthly!$D$7:$BK$7,C$4,Engine_Monthly!$D$49:$BK$49) -> 0.2115167 | D22: =AVERAGEIF(Engine_Monthly!$D$7:$BK$7,D$4,Engine_Monthly!$D$49:$BK$49) -> 6.7212498 | E22: =AVERAGEIF(Engine_Monthly!$D$7:$BK$7,E$4,Engine_Monthly!$D$49:$BK$49) -> 44.191916 | F22: =AVERAGEIF(Engine_Monthly!$D$7:$BK$7,F$4,Engine_Monthly!$D$49:$BK$49) -> 139.47733 | G22: =AVERAGEIF(Engine_Monthly!$D$7:$BK$7,G$4,Engine_Monthly!$D$49:$BK$49) -> 304.57585
A23: Critical machines covered | B23: # | C23: =C21*Inputs!$C$42 -> 21.218707 | D23: =D21*Inputs!$C$42 -> 351.97182 | E23: =E21*Inputs!$C$42 -> 1544.9919 | F23: =F21*Inputs!$C$42 -> 4068.0006 | G23: =G21*Inputs!$C$42 -> 8000.0002 | H23: Live plants × machines per plant (Inputs).
A25: ARR & CONTRACT VALUE (subscription only; excludes one-time fees)
A26: Opening ARR | B26: ₹ lakh | C26: =0 -> 0 | D26: =C30 -> 30.996799 | E26: =D30 -> 552.94498 | F26: =E30 -> 2619.6435 | G26: =F30 -> 7429.6244
A27: + New plants | B27: ₹ lakh | C27: =SUMIF(Engine_Monthly!$D$7:$BK$7,C$4,Engine_Monthly!$D$55:$BK$55) -> 30.834375 | D27: =SUMIF(Engine_Monthly!$D$7:$BK$7,D$4,Engine_Monthly!$D$55:$BK$55) -> 514.38272 | E27: =SUMIF(Engine_Monthly!$D$7:$BK$7,E$4,Engine_Monthly!$D$55:$BK$55) -> 2007.5363 | F27: =SUMIF(Engine_Monthly!$D$7:$BK$7,F$4,Engine_Monthly!$D$55:$BK$55) -> 4601.7143 | G27: =SUMIF(Engine_Monthly!$D$7:$BK$7,G$4,Engine_Monthly!$D$55:$BK$55) -> 7816.4359
A28: + Expansion & escalation | B28: ₹ lakh | C28: =SUMIF(Engine_Monthly!$D$7:$BK$7,C$4,Engine_Monthly!$D$54:$BK$54) -> 0.49749492 | D28: =SUMIF(Engine_Monthly!$D$7:$BK$7,D$4,Engine_Monthly!$D$54:$BK$54) -> 23.172571 | E28: =SUMIF(Engine_Monthly!$D$7:$BK$7,E$4,Engine_Monthly!$D$54:$BK$54) -> 181.21016 | F28: =SUMIF(Engine_Monthly!$D$7:$BK$7,F$4,Engine_Monthly!$D$54:$BK$54) -> 637.90821 | G28: =SUMIF(Engine_Monthly!$D$7:$BK$7,G$4,Engine_Monthly!$D$54:$BK$54) -> 1530.6059
A29: − Churned | B29: ₹ lakh | C29: =-SUMIF(Engine_Monthly!$D$7:$BK$7,C$4,Engine_Monthly!$D$53:$BK$53) -> -0.33507096 | D29: =-SUMIF(Engine_Monthly!$D$7:$BK$7,D$4,Engine_Monthly!$D$53:$BK$53) -> -15.607105 | E29: =-SUMIF(Engine_Monthly!$D$7:$BK$7,E$4,Engine_Monthly!$D$53:$BK$53) -> -122.048 | F29: =-SUMIF(Engine_Monthly!$D$7:$BK$7,F$4,Engine_Monthly!$D$53:$BK$53) -> -429.64161 | G29: =-SUMIF(Engine_Monthly!$D$7:$BK$7,G$4,Engine_Monthly!$D$53:$BK$53) -> -1030.8881
A30: Closing ARR | B30: ₹ lakh | C30: =SUM(C26:C29) -> 30.996799 | D30: =SUM(D26:D29) -> 552.94498 | E30: =SUM(E26:E29) -> 2619.6435 | F30: =SUM(F26:F29) -> 7429.6244 | G30: =SUM(G26:G29) -> 15745.778
A31: Check vs engine (should be 0) | B31: ₹ lakh | C31: =ROUND(C30-INDEX(Engine_Monthly!$D$56:$BK$56,1,C$4*12),3) -> 0 | D31: =ROUND(D30-INDEX(Engine_Monthly!$D$56:$BK$56,1,D$4*12),3) -> 0 | E31: =ROUND(E30-INDEX(Engine_Monthly!$D$56:$BK$56,1,E$4*12),3) -> 0 | F31: =ROUND(F30-INDEX(Engine_Monthly!$D$56:$BK$56,1,F$4*12),3) -> 0 | G31: =ROUND(G30-INDEX(Engine_Monthly!$D$56:$BK$56,1,G$4*12),3) -> 0
A32: Closing MRR | B32: ₹ lakh | C32: =INDEX(Engine_Monthly!$D$57:$BK$57,1,C$4*12) -> 2.5830666 | D32: =INDEX(Engine_Monthly!$D$57:$BK$57,1,D$4*12) -> 46.078748 | E32: =INDEX(Engine_Monthly!$D$57:$BK$57,1,E$4*12) -> 218.30362 | F32: =INDEX(Engine_Monthly!$D$57:$BK$57,1,F$4*12) -> 619.13536 | G32: =INDEX(Engine_Monthly!$D$57:$BK$57,1,G$4*12) -> 1312.1482
A33: New-customer ACV (blended list price) | B33: ₹ lakh | C33: =INDEX(Engine_Monthly!$D$50:$BK$50,1,C$4*12) -> 28.75 | D33: =INDEX(Engine_Monthly!$D$50:$BK$50,1,D$4*12) -> 30.1875 | E33: =INDEX(Engine_Monthly!$D$50:$BK$50,1,E$4*12) -> 31.696875 | F33: =INDEX(Engine_Monthly!$D$50:$BK$50,1,F$4*12) -> 33.281719 | G33: =INDEX(Engine_Monthly!$D$50:$BK$50,1,G$4*12) -> 34.945805
A34: Average ARR per live plant (year end) | B34: ₹ lakh | C34: =IFERROR(C30/C21,0) -> 29.216482 | D34: =IFERROR(D30/D21,0) -> 31.419844 | E34: =IFERROR(E30/E21,0) -> 33.91142 | F34: =IFERROR(F30/F21,0) -> 36.527154 | G34: =IFERROR(G30/G21,0) -> 39.364444
A35: Renewal rate (1 − logo churn) | B35: % | C35: =1-MIN(0.95,Inputs!$C$50*Inputs!$C$127) -> 0.91 | D35: =1-MIN(0.95,Inputs!$C$50*Inputs!$C$127) -> 0.91 | E35: =1-MIN(0.95,Inputs!$C$50*Inputs!$C$127) -> 0.91 | F35: =1-MIN(0.95,Inputs!$C$50*Inputs!$C$127) -> 0.91 | G35: =1-MIN(0.95,Inputs!$C$50*Inputs!$C$127) -> 0.91
A37: REVENUE BY STREAM (recognised)
A38: Subscription | B38: ₹ lakh | C38: =SUMIF(Engine_Monthly!$D$7:$BK$7,C$4,Engine_Monthly!$D$60:$BK$60) -> 4.8583551 | D38: =SUMIF(Engine_Monthly!$D$7:$BK$7,D$4,Engine_Monthly!$D$60:$BK$60) -> 187.88507 | E38: =SUMIF(Engine_Monthly!$D$7:$BK$7,E$4,Engine_Monthly!$D$60:$BK$60) -> 1385.3103 | F38: =SUMIF(Engine_Monthly!$D$7:$BK$7,F$4,Engine_Monthly!$D$60:$BK$60) -> 4773.9397 | G38: =SUMIF(Engine_Monthly!$D$7:$BK$7,G$4,Engine_Monthly!$D$60:$BK$60) -> 11320.283
A39: Implementation | B39: ₹ lakh | C39: =SUMIF(Engine_Monthly!$D$7:$BK$7,C$4,Engine_Monthly!$D$61:$BK$61) -> 6.595875 | D39: =SUMIF(Engine_Monthly!$D$7:$BK$7,D$4,Engine_Monthly!$D$61:$BK$61) -> 110.03317 | E39: =SUMIF(Engine_Monthly!$D$7:$BK$7,E$4,Engine_Monthly!$D$61:$BK$61) -> 429.43821 | F39: =SUMIF(Engine_Monthly!$D$7:$BK$7,F$4,Engine_Monthly!$D$61:$BK$61) -> 984.36671 | G39: =SUMIF(Engine_Monthly!$D$7:$BK$7,G$4,Engine_Monthly!$D$61:$BK$61) -> 1672.0376
A40: Paid pilots | B40: ₹ lakh | C40: =SUMIF(Engine_Monthly!$D$7:$BK$7,C$4,Engine_Monthly!$D$62:$BK$62) -> 14.75 | D40: =SUMIF(Engine_Monthly!$D$7:$BK$7,D$4,Engine_Monthly!$D$62:$BK$62) -> 136.40539 | E40: =SUMIF(Engine_Monthly!$D$7:$BK$7,E$4,Engine_Monthly!$D$62:$BK$62) -> 397.41887 | F40: =SUMIF(Engine_Monthly!$D$7:$BK$7,F$4,Engine_Monthly!$D$62:$BK$62) -> 758.63505 | G40: =SUMIF(Engine_Monthly!$D$7:$BK$7,G$4,Engine_Monthly!$D$62:$BK$62) -> 1138.9762
A41: IoT kit resale | B41: ₹ lakh | C41: =SUMIF(Engine_Monthly!$D$7:$BK$7,C$4,Engine_Monthly!$D$63:$BK$63) -> 2.0645625 | D41: =SUMIF(Engine_Monthly!$D$7:$BK$7,D$4,Engine_Monthly!$D$63:$BK$63) -> 32.801217 | E41: =SUMIF(Engine_Monthly!$D$7:$BK$7,E$4,Engine_Monthly!$D$63:$BK$63) -> 121.92077 | F41: =SUMIF(Engine_Monthly!$D$7:$BK$7,F$4,Engine_Monthly!$D$63:$BK$63) -> 266.16113 | G41: =SUMIF(Engine_Monthly!$D$7:$BK$7,G$4,Engine_Monthly!$D$63:$BK$63) -> 430.57068
A42: Gain-share (performance-linked; not ARR) | B42: ₹ lakh | C42: =SUMIF(Engine_Monthly!$D$7:$BK$7,C$4,Engine_Monthly!$D$64:$BK$64) -> 0.36883224 | D42: =SUMIF(Engine_Monthly!$D$7:$BK$7,D$4,Engine_Monthly!$D$64:$BK$64) -> 11.720179 | E42: =SUMIF(Engine_Monthly!$D$7:$BK$7,E$4,Engine_Monthly!$D$64:$BK$64) -> 77.059653 | F42: =SUMIF(Engine_Monthly!$D$7:$BK$7,F$4,Engine_Monthly!$D$64:$BK$64) -> 243.2136 | G42: =SUMIF(Engine_Monthly!$D$7:$BK$7,G$4,Engine_Monthly!$D$64:$BK$64) -> 531.10413
A43: Total revenue | B43: ₹ lakh | C43: =SUM(C38:C42) -> 28.637625 | D43: =SUM(D38:D42) -> 478.84504 | E43: =SUM(E38:E42) -> 2411.1478 | F43: =SUM(F38:F42) -> 7026.3162 | G43: =SUM(G38:G42) -> 15092.972
A44: Check vs P&L (should be 0) | B44: ₹ lakh | C44: =ROUND(C43-7_Financials!C11,3) -> 0 | D44: =ROUND(D43-7_Financials!D11,3) -> 0 | E44: =ROUND(E43-7_Financials!E11,3) -> 0 | F44: =ROUND(F43-7_Financials!F11,3) -> 0 | G44: =ROUND(G43-7_Financials!G11,3) -> 0
...

Sheet 5_Cost_of_Service
A1: 5. COST OF SERVICE & GROSS MARGIN
A2: Recurring cost to serve vs one-time implementation cost, shown separately.
A3: ₹ lakh | B3: Unit | C3: =INDEX(Engine_Monthly!$D$10:$BK$10,1,12) -> FY27 | D3: =INDEX(Engine_Monthly!$D$10:$BK$10,1,24) -> FY28 | E3: =INDEX(Engine_Monthly!$D$10:$BK$10,1,36) -> FY29 | F3: =INDEX(Engine_Monthly!$D$10:$BK$10,1,48) -> FY30 | G3: =INDEX(Engine_Monthly!$D$10:$BK$10,1,60) -> FY31
A4: Fiscal-year index | C4: 1 | D4: 2 | E4: 3 | F4: 4 | G4: 5
A6: RECURRING COST TO SERVE (cost of SaaS revenue)
A7: Cloud hosting & compute | B7: ₹ lakh | C7: =SUMIF(Engine_Monthly!$D$7:$BK$7,C$4,Engine_Monthly!$D$70:$BK$70) -> 1.416674 | D7: =SUMIF(Engine_Monthly!$D$7:$BK$7,D$4,Engine_Monthly!$D$70:$BK$70) -> 16.248708 | E7: =SUMIF(Engine_Monthly!$D$7:$BK$7,E$4,Engine_Monthly!$D$70:$BK$70) -> 63.630216 | F7: =SUMIF(Engine_Monthly!$D$7:$BK$7,F$4,Engine_Monthly!$D$70:$BK$70) -> 155.08739 | G7: =SUMIF(Engine_Monthly!$D$7:$BK$7,G$4,Engine_Monthly!$D$70:$BK$70) -> 286.31337
A8: AI inference & solver | B8: ₹ lakh | C8: =SUMIF(Engine_Monthly!$D$7:$BK$7,C$4,Engine_Monthly!$D$71:$BK$71) -> 0.60714601 | D8: =SUMIF(Engine_Monthly!$D$7:$BK$7,D$4,Engine_Monthly!$D$71:$BK$71) -> 6.9637318 | E8: =SUMIF(Engine_Monthly!$D$7:$BK$7,E$4,Engine_Monthly!$D$71:$BK$71) -> 27.270093 | F8: =SUMIF(Engine_Monthly!$D$7:$BK$7,F$4,Engine_Monthly!$D$71:$BK$71) -> 66.466026 | G8: =SUMIF(Engine_Monthly!$D$7:$BK$7,G$4,Engine_Monthly!$D$71:$BK$71) -> 122.70573
A9: Industrial data ingestion & storage | B9: ₹ lakh | C9: =SUMIF(Engine_Monthly!$D$7:$BK$7,C$4,Engine_Monthly!$D$72:$BK$72) -> 0.40476401 | D9: =SUMIF(Engine_Monthly!$D$7:$BK$7,D$4,Engine_Monthly!$D$72:$BK$72) -> 4.6424879 | E9: =SUMIF(Engine_Monthly!$D$7:$BK$7,E$4,Engine_Monthly!$D$72:$BK$72) -> 18.180062 | F9: =SUMIF(Engine_Monthly!$D$7:$BK$7,F$4,Engine_Monthly!$D$72:$BK$72) -> 44.310684 | G9: =SUMIF(Engine_Monthly!$D$7:$BK$7,G$4,Engine_Monthly!$D$72:$BK$72) -> 81.803821
A10: Third-party software licences | B10: ₹ lakh | C10: =SUMIF(Engine_Monthly!$D$7:$BK$7,C$4,Engine_Monthly!$D$73:$BK$73) -> 0.50595501 | D10: =SUMIF(Engine_Monthly!$D$7:$BK$7,D$4,Engine_Monthly!$D$73:$BK$73) -> 5.8031099 | E10: =SUMIF(Engine_Monthly!$D$7:$BK$7,E$4,Engine_Monthly!$D$73:$BK$73) -> 22.725077 | F10: =SUMIF(Engine_Monthly!$D$7:$BK$7,F$4,Engine_Monthly!$D$73:$BK$73) -> 55.388355 | G10: =SUMIF(Engine_Monthly!$D$7:$BK$7,G$4,Engine_Monthly!$D$73:$BK$73) -> 102.25478
A11: Model monitoring & retraining | B11: ₹ lakh | C11: =SUMIF(Engine_Monthly!$D$7:$BK$7,C$4,Engine_Monthly!$D$74:$BK$74) -> 0.50595501 | D11: =SUMIF(Engine_Monthly!$D$7:$BK$7,D$4,Engine_Monthly!$D$74:$BK$74) -> 5.8031099 | E11: =SUMIF(Engine_Monthly!$D$7:$BK$7,E$4,Engine_Monthly!$D$74:$BK$74) -> 22.725077 | F11: =SUMIF(Engine_Monthly!$D$7:$BK$7,F$4,Engine_Monthly!$D$74:$BK$74) -> 55.388355 | G11: =SUMIF(Engine_Monthly!$D$7:$BK$7,G$4,Engine_Monthly!$D$74:$BK$74) -> 102.25478
A12: Cybersecurity & data management (fixed) | B12: ₹ lakh | C12: =SUMIF(Engine_Monthly!$D$7:$BK$7,C$4,Engine_Monthly!$D$75:$BK$75) -> 15 | D12: =SUMIF(Engine_Monthly!$D$7:$BK$7,D$4,Engine_Monthly!$D$75:$BK$75) -> 18.9 | E12: =SUMIF(Engine_Monthly!$D$7:$BK$7,E$4,Engine_Monthly!$D$75:$BK$75) -> 19.845 | F12: =SUMIF(Engine_Monthly!$D$7:$BK$7,F$4,Engine_Monthly!$D$75:$BK$75) -> 20.83725 | G12: =SUMIF(Engine_Monthly!$D$7:$BK$7,G$4,Engine_Monthly!$D$75:$BK$75) -> 21.879113
A13: Customer success | B13: ₹ lakh | C13: =SUMIF(Engine_Monthly!$D$7:$BK$7,C$4,Engine_Monthly!$D$78:$BK$78) -> 3.36 | D13: =SUMIF(Engine_Monthly!$D$7:$BK$7,D$4,Engine_Monthly!$D$78:$BK$78) -> 10.8864 | E13: =SUMIF(Engine_Monthly!$D$7:$BK$7,E$4,Engine_Monthly!$D$78:$BK$78) -> 26.453952 | F13: =SUMIF(Engine_Monthly!$D$7:$BK$7,F$4,Engine_Monthly!$D$78:$BK$78) -> 77.24554 | G13: =SUMIF(Engine_Monthly!$D$7:$BK$7,G$4,Engine_Monthly!$D$78:$BK$78) -> 173.70723
A14: Technical support | B14: ₹ lakh | C14: =SUMIF(Engine_Monthly!$D$7:$BK$7,C$4,Engine_Monthly!$D$79:$BK$79) -> 2.24 | D14: =SUMIF(Engine_Monthly!$D$7:$BK$7,D$4,Engine_Monthly!$D$79:$BK$79) -> 7.2576 | E14: =SUMIF(Engine_Monthly!$D$7:$BK$7,E$4,Engine_Monthly!$D$79:$BK$79) -> 15.676416 | F14: =SUMIF(Engine_Monthly!$D$7:$BK$7,F$4,Engine_Monthly!$D$79:$BK$79) -> 43.031762 | G14: =SUMIF(Engine_Monthly!$D$7:$BK$7,G$4,Engine_Monthly!$D$79:$BK$79) -> 97.519849
A15: Total cost of SaaS revenue | B15: ₹ lakh | C15: =SUMIF(Engine_Monthly!$D$7:$BK$7,C$4,Engine_Monthly!$D$80:$BK$80) -> 24.040494 | D15: =SUMIF(Engine_Monthly!$D$7:$BK$7,D$4,Engine_Monthly!$D$80:$BK$80) -> 76.505147 | E15: =SUMIF(Engine_Monthly!$D$7:$BK$7,E$4,Engine_Monthly!$D$80:$BK$80) -> 216.50589 | F15: =SUMIF(Engine_Monthly!$D$7:$BK$7,F$4,Engine_Monthly!$D$80:$BK$80) -> 517.75536 | G15: =SUMIF(Engine_Monthly!$D$7:$BK$7,G$4,Engine_Monthly!$D$80:$BK$80) -> 988.43867
A16: SaaS revenue (subscription only; gain-share excluded) | B16: ₹ lakh | C16: =SUMIF(Engine_Monthly!$D$7:$BK$7,C$4,Engine_Monthly!$D$60:$BK$60) -> 4.8583551 | D16: =SUMIF(Engine_Monthly!$D$7:$BK$7,D$4,Engine_Monthly!$D$60:$BK$60) -> 187.88507 | E16: =SUMIF(Engine_Monthly!$D$7:$BK$7,E$4,Engine_Monthly!$D$60:$BK$60) -> 1385.3103 | F16: =SUMIF(Engine_Monthly!$D$7:$BK$7,F$4,Engine_Monthly!$D$60:$BK$60) -> 4773.9397 | G16: =SUMIF(Engine_Monthly!$D$7:$BK$7,G$4,Engine_Monthly!$D$60:$BK$60) -> 11320.283
A17: SaaS gross margin | B17: % | C17: =IFERROR(1-C15/C16,0) -> -3.9482785 | D17: =IFERROR(1-D15/D16,0) -> 0.59280881 | E17: =IFERROR(1-E15/E16,0) -> 0.84371307 | F17: =IFERROR(1-F15/F16,0) -> 0.89154548 | G17: =IFERROR(1-G15/G16,0) -> 0.91268428
A18: Recurring cost to serve per average live plant | B18: ₹ lakh | C18: =IF(AVERAGEIF(Engine_Monthly!$D$7:$BK$7,C$4,Engine_Monthly!$D$49:$BK$49)<3,"n.m.",C15/AVERAGEIF(Engine_Monthly!$D$7:$BK$7,C$4,Engine_Monthly!$D$49:$BK$49)) -> n.m. | D18: =IF(AVERAGEIF(Engine_Monthly!$D$7:$BK$7,D$4,Engine_Monthly!$D$49:$BK$49)<3,"n.m.",D15/AVERAGEIF(Engine_Monthly!$D$7:$BK$7,D$4,Engine_Monthly!$D$49:$BK$49)) -> 11.382578 | E18: =IF(AVERAGEIF(Engine_Monthly!$D$7:$BK$7,E$4,Engine_Monthly!$D$49:$BK$49)<3,"n.m.",E15/AVERAGEIF(Engine_Monthly!$D$7:$BK$7,E$4,Engine_Monthly!$D$49:$BK$49)) -> 4.8992194 | F18: =IF(AVERAGEIF(Engine_Monthly!$D$7:$BK$7,F$4,Engine_Monthly!$D$49:$BK$49)<3,"n.m.",F15/AVERAGEIF(Engine_Monthly!$D$7:$BK$7,F$4,Engine_Monthly!$D$49:$BK$49)) -> 3.7121112 | G18: =IF(AVERAGEIF(Engine_Monthly!$D$7:$BK$7,G$4,Engine_Monthly!$D$49:$BK$49)<3,"n.m.",G15/AVERAGEIF(Engine_Monthly!$D$7:$BK$7,G$4,Engine_Monthly!$D$49:$BK$49)) -> 3.2452957
A20: ONE-TIME DEPLOYMENT COST (implementation & pilots)
A21: Implementation engineers (salaries) | B21: ₹ lakh | C21: =SUMIF(Engine_Monthly!$D$7:$BK$7,C$4,Engine_Monthly!$D$81:$BK$81) -> 9.3333333 | D21: =SUMIF(Engine_Monthly!$D$7:$BK$7,D$4,Engine_Monthly!$D$81:$BK$81) -> 47.376 | E21: =SUMIF(Engine_Monthly!$D$7:$BK$7,E$4,Engine_Monthly!$D$81:$BK$81) -> 141.5232 | F21: =SUMIF(Engine_Monthly!$D$7:$BK$7,F$4,Engine_Monthly!$D$81:$BK$81) -> 296.28426 | G21: =SUMIF(Engine_Monthly!$D$7:$BK$7,G$4,Engine_Monthly!$D$81:$BK$81) -> 487.59924
A22: On-site deployment, integration, travel, pilot costs | B22: ₹ lakh | C22: =SUMIF(Engine_Monthly!$D$7:$BK$7,C$4,Engine_Monthly!$D$82:$BK$82) -> 9.88125 | D22: =SUMIF(Engine_Monthly!$D$7:$BK$7,D$4,Engine_Monthly!$D$82:$BK$82) -> 107.99923 | E22: =SUMIF(Engine_Monthly!$D$7:$BK$7,E$4,Engine_Monthly!$D$82:$BK$82) -> 362.02986 | F22: =SUMIF(Engine_Monthly!$D$7:$BK$7,F$4,Engine_Monthly!$D$82:$BK$82) -> 766.58896 | G22: =SUMIF(Engine_Monthly!$D$7:$BK$7,G$4,Engine_Monthly!$D$82:$BK$82) -> 1248.2808
A23: Total cost of implementation & pilot revenue | B23: ₹ lakh | C23: =SUMIF(Engine_Monthly!$D$7:$BK$7,C$4,Engine_Monthly!$D$83:$BK$83) -> 19.214583 | D23: =SUMIF(Engine_Monthly!$D$7:$BK$7,D$4,Engine_Monthly!$D$83:$BK$83) -> 155.37523 | E23: =SUMIF(Engine_Monthly!$D$7:$BK$7,E$4,Engine_Monthly!$D$83:$BK$83) -> 503.55306 | F23: =SUMIF(Engine_Monthly!$D$7:$BK$7,F$4,Engine_Monthly!$D$83:$BK$83) -> 1062.8732 | G23: =SUMIF(Engine_Monthly!$D$7:$BK$7,G$4,Engine_Monthly!$D$83:$BK$83) -> 1735.8801
A24: Implementation + pilot revenue | B24: ₹ lakh | C24: =SUMIF(Engine_Monthly!$D$7:$BK$7,C$4,Engine_Monthly!$D$61:$BK$61)+SUMIF(Engine_Monthly!$D$7:$BK$7,C$4,Engine_Monthly!$D$62:$BK$62) -> 21.345875 | D24: =SUMIF(Engine_Monthly!$D$7:$BK$7,D$4,Engine_Monthly!$D$61:$BK$61)+SUMIF(Engine_Monthly!$D$7:$BK$7,D$4,Engine_Monthly!$D$62:$BK$62) -> 246.43856 | E24: =SUMIF(Engine_Monthly!$D$7:$BK$7,E$4,Engine_Monthly!$D$61:$BK$61)+SUMIF(Engine_Monthly!$D$7:$BK$7,E$4,Engine_Monthly!$D$62:$BK$62) -> 826.85708 | F24: =SUMIF(Engine_Monthly!$D$7:$BK$7,F$4,Engine_Monthly!$D$61:$BK$61)+SUMIF(Engine_Monthly!$D$7:$BK$7,F$4,Engine_Monthly!$D$62:$BK$62) -> 1743.0018 | G24: =SUMIF(Engine_Monthly!$D$7:$BK$7,G$4,Engine_Monthly!$D$61:$BK$61)+SUMIF(Engine_Monthly!$D$7:$BK$7,G$4,Engine_Monthly!$D$62:$BK$62) -> 2811.0138
A25: Services gross margin | B25: % | C25: =IFERROR(1-C23/C24,0) -> 0.099845599 | D25: =IFERROR(1-D23/D24,0) -> 0.36951739 | E25: =IFERROR(1-E23/E24,0) -> 0.39100351 | F25: =IFERROR(1-F23/F24,0) -> 0.3902053 | G25: =IFERROR(1-G23/G24,0) -> 0.38247188
A26: Deployment cost per plant gone live | B26: ₹ lakh | C26: =IFERROR(C23/SUMIF(Engine_Monthly!$D$7:$BK$7,C$4,Engine_Monthly!$D$42:$BK$42),0) -> 17.915695 | D26: =IFERROR(D23/SUMIF(Engine_Monthly!$D$7:$BK$7,D$4,Engine_Monthly!$D$42:$BK$42),0) -> 9.1184824 | E26: =IFERROR(E23/SUMIF(Engine_Monthly!$D$7:$BK$7,E$4,Engine_Monthly!$D$42:$BK$42),0) -> 7.9505701 | F26: =IFERROR(F23/SUMIF(Engine_Monthly!$D$7:$BK$7,F$4,Engine_Monthly!$D$42:$BK$42),0) -> 7.6871891 | G26: =IFERROR(G23/SUMIF(Engine_Monthly!$D$7:$BK$7,G$4,Engine_Monthly!$D$42:$BK$42),0) -> 7.7607912 | H26: Includes pilot costs of prospects that did not convert.
A27: Implementation fee per plant gone live | B27: ₹ lakh | C27: =IFERROR(SUMIF(Engine_Monthly!$D$7:$BK$7,C$4,Engine_Monthly!$D$61:$BK$61)/SUMIF(Engine_Monthly!$D$7:$BK$7,C$4,Engine_Monthly!$D$42:$BK$42),0) -> 6.15 | D27: =IFERROR(SUMIF(Engine_Monthly!$D$7:$BK$7,D$4,Engine_Monthly!$D$61:$BK$61)/SUMIF(Engine_Monthly!$D$7:$BK$7,D$4,Engine_Monthly!$D$42:$BK$42),0) -> 6.4575 | E27: =IFERROR(SUMIF(Engine_Monthly!$D$7:$BK$7,E$4,Engine_Monthly!$D$61:$BK$61)/SUMIF(Engine_Monthly!$D$7:$BK$7,E$4,Engine_Monthly!$D$42:$BK$42),0) -> 6.780375 | F27: =IFERROR(SUMIF(Engine_Monthly!$D$7:$BK$7,F$4,Engine_Monthly!$D$61:$BK$61)/SUMIF(Engine_Monthly!$D$7:$BK$7,F$4,Engine_Monthly!$D$42:$BK$42),0) -> 7.1193938 | G27: =IFERROR(SUMIF(Engine_Monthly!$D$7:$BK$7,G$4,Engine_Monthly!$D$61:$BK$61)/SUMIF(Engine_Monthly!$D$7:$BK$7,G$4,Engine_Monthly!$D$42:$BK$42),0) -> 7.4753634
A29: HARDWARE (optional IoT kit)
A30: IoT kit revenue | B30: ₹ lakh | C30: =SUMIF(Engine_Monthly!$D$7:$BK$7,C$4,Engine_Monthly!$D$63:$BK$63) -> 2.0645625 | D30: =SUMIF(Engine_Monthly!$D$7:$BK$7,D$4,Engine_Monthly!$D$63:$BK$63) -> 32.801217 | E30: =SUMIF(Engine_Monthly!$D$7:$BK$7,E$4,Engine_Monthly!$D$63:$BK$63) -> 121.92077 | F30: =SUMIF(Engine_Monthly!$D$7:$BK$7,F$4,Engine_Monthly!$D$63:$BK$63) -> 266.16113 | G30: =SUMIF(Engine_Monthly!$D$7:$BK$7,G$4,Engine_Monthly!$D$63:$BK$63) -> 430.57068
A31: IoT kit cost | B31: ₹ lakh | C31: =SUMIF(Engine_Monthly!$D$7:$BK$7,C$4,Engine_Monthly!$D$84:$BK$84) -> 1.876875 | D31: =SUMIF(Engine_Monthly!$D$7:$BK$7,D$4,Engine_Monthly!$D$84:$BK$84) -> 29.819288 | E31: =SUMIF(Engine_Monthly!$D$7:$BK$7,E$4,Engine_Monthly!$D$84:$BK$84) -> 110.83706 | F31: =SUMIF(Engine_Monthly!$D$7:$BK$7,F$4,Engine_Monthly!$D$84:$BK$84) -> 241.96467 | G31: =SUMIF(Engine_Monthly!$D$7:$BK$7,G$4,Engine_Monthly!$D$84:$BK$84) -> 391.4279
